Workbook

Sheet Summary
A1: GenAI Architect Learning Tracker (.NET Architect -> Python -> GenAI -> Agentic AI)
A2: Follow the 'Learning Path' sheet in Seq # order. 1 Topic = 1 Reel (any length). Update status via dropdowns in the track sheets.
A4: Track | B4: Total Subtopics | C4: Done | D4: In Progress | E4: Not Started | F4: Progress % | G4: P1 Subtopics | H4: P1 Done | I4: Scripts Ready/Made
A5: Python | B5: =COUNTA(Python!F2:F121) -> 120 | C5: =COUNTIF(Python!I2:I121,"Done") -> 0 | D5: =COUNTIF(Python!I2:I121,"In Progress") -> 0 | E5: =COUNTIF(Python!I2:I121,"Not Started") -> 120 | F5: =IF(B5=0,0,C5/B5) -> 0 | G5: =COUNTIF(Python!H2:H121,"P1") -> 105 | H5: =COUNTIFS(Python!H2:H121,"P1",Python!I2:I121,"Done") -> 0 | I5: =COUNTIF(Python!J2:J121,"Script Ready")+COUNTIF(Python!J2:J121,"Reel Made")+COUNTIF(Python!J2:J121,"Watched") -> 0
A6: GenAI | B6: =COUNTA(GenAI!F2:F150) -> 149 | C6: =COUNTIF(GenAI!I2:I150,"Done") -> 0 | D6: =COUNTIF(GenAI!I2:I150,"In Progress") -> 0 | E6: =COUNTIF(GenAI!I2:I150,"Not Started") -> 149 | F6: =IF(B6=0,0,C6/B6) -> 0 | G6: =COUNTIF(GenAI!H2:H150,"P1") -> 124 | H6: =COUNTIFS(GenAI!H2:H150,"P1",GenAI!I2:I150,"Done") -> 0 | I6: =COUNTIF(GenAI!J2:J150,"Script Ready")+COUNTIF(GenAI!J2:J150,"Reel Made")+COUNTIF(GenAI!J2:J150,"Watched") -> 0
A7: Agentic AI | B7: =COUNTA('Agentic AI'!F2:F124) -> 123 | C7: =COUNTIF('Agentic AI'!I2:I124,"Done") -> 0 | D7: =COUNTIF('Agentic AI'!I2:I124,"In Progress") -> 0 | E7: =COUNTIF('Agentic AI'!I2:I124,"Not Started") -> 123 | F7: =IF(B7=0,0,C7/B7) -> 0 | G7: =COUNTIF('Agentic AI'!H2:H124,"P1") -> 104 | H7: =COUNTIFS('Agentic AI'!H2:H124,"P1",'Agentic AI'!I2:I124,"Done") -> 0 | I7: =COUNTIF('Agentic AI'!J2:J124,"Script Ready")+COUNTIF('Agentic AI'!J2:J124,"Reel Made")+COUNTIF('Agentic AI'!J2:J124,"Watched") -> 0
A8: TOTAL | B8: =SUM(B5:B7) -> 392 | C8: =SUM(C5:C7) -> 0 | D8: =SUM(D5:D7) -> 0 | E8: =SUM(E5:E7) -> 392 | F8: =IF(B8=0,0,C8/B8) -> 0 | G8: =SUM(G5:G7) -> 333 | H8: =SUM(H5:H7) -> 0 | I8: =SUM(I5:I7) -> 0
A10: Reels done (all subtopics Done) | B10: =COUNTIF('Learning Path'!J2:J81,"Done") -> 0 | C10: of 80
A12: LEGEND
A13: Priority: P1 = Must (architect-critical) P2 = Should P3 = Later
A14: Learning Path = dependency order (each reel builds on the previous). Do not skip stages.
A15: Items marked '(verify)' are fast-changing: re-check before making a reel.
A16: Reel structure: Intuition -> Practical example -> Technical details -> Recap -> 3 quiz Qs -> 1 mini exercise.
A17: Fast-changing facts used: MCP spec 2026-07-28 (stateless core); Microsoft Agent Framework merges AutoGen + Semantic Kernel (web search, Oct 2026).

Sheet Learning Path
A1: Seq # | B1: Stage | C1: Reel ID | D1: Track | E1: Topic (1 Reel) | F1: Priority | G1: Subtopics | H1: Est. Length | I1: Prerequisite Reel(s) | J1: Reel Status (auto)
A2: 1 | B2: 1. Python Core | C2: PY-01 | D2: Python | E2: Setup & Tooling | F2: P1 | G2: =COUNTIF(Python!$C$2:$C$121,C2) -> 5 | H2: =IF(G2<=4,"3-4 min",IF(G2<=6,"6-8 min","10-12 min")) -> 6-8 min | I2: - | J2: =IF(COUNTIFS(Python!$C$2:$C$121,C2,Python!$I$2:$I$121,"Done")=G2,"Done",IF(COUNTIFS(Python!$C$2:$C$121,C2,Python!$I$2:$I$121,"Not Started")=G2,"Not Started","In Progress")) -> Not Started
A3: 2 | B3: 1. Python Core | C3: PY-02 | D3: Python | E3: Syntax Basics | F3: P1 | G3: =COUNTIF(Python!$C$2:$C$121,C3) -> 5 | H3: =IF(G3<=4,"3-4 min",IF(G3<=6,"6-8 min","10-12 min")) -> 6-8 min | I3: PY-01 | J3: =IF(COUNTIFS(Python!$C$2:$C$121,C3,Python!$I$2:$I$121,"Done")=G3,"Done",IF(COUNTIFS(Python!$C$2:$C$121,C3,Python!$I$2:$I$121,"Not Started")=G3,"Not Started","In Progress")) -> Not Started
A4: 3 | B4: 1. Python Core | C4: PY-03 | D4: Python | E4: Core Data Structures | F4: P1 | G4: =COUNTIF(Python!$C$2:$C$121,C4) -> 5 | H4: =IF(G4<=4,"3-4 min",IF(G4<=6,"6-8 min","10-12 min")) -> 6-8 min | I4: PY-02 | J4: =IF(COUNTIFS(Python!$C$2:$C$121,C4,Python!$I$2:$I$121,"Done")=G4,"Done",IF(COUNTIFS(Python!$C$2:$C$121,C4,Python!$I$2:$I$121,"Not Started")=G4,"Not Started","In Progress")) -> Not Started
A5: 4 | B5: 1. Python Core | C5: PY-04 | D5: Python | E5: Functions | F5: P1 | G5: =COUNTIF(Python!$C$2:$C$121,C5) -> 5 | H5: =IF(G5<=4,"3-4 min",IF(G5<=6,"6-8 min","10-12 min")) -> 6-8 min | I5: PY-03 | J5: =IF(COUNTIFS(Python!$C$2:$C$121,C5,Python!$I$2:$I$121,"Done")=G5,"Done",IF(COUNTIFS(Python!$C$2:$C$121,C5,Python!$I$2:$I$121,"Not Started")=G5,"Not Started","In Progress")) -> Not Started
A6: 5 | B6: 1. Python Core | C6: PY-05 | D6: Python | E6: OOP in Python | F6: P1 | G6: =COUNTIF(Python!$C$2:$C$121,C6) -> 6 | H6: =IF(G6<=4,"3-4 min",IF(G6<=6,"6-8 min","10-12 min")) -> 6-8 min | I6: PY-04 | J6: =IF(COUNTIFS(Python!$C$2:$C$121,C6,Python!$I$2:$I$121,"Done")=G6,"Done",IF(COUNTIFS(Python!$C$2:$C$121,C6,Python!$I$2:$I$121,"Not Started")=G6,"Not Started","In Progress")) -> Not Started
A7: 6 | B7: 1. Python Core | C7: PY-06 | D7: Python | E7: Modules & Project Structure | F7: P1 | G7: =COUNTIF(Python!$C$2:$C$121,C7) -> 4 | H7: =IF(G7<=4,"3-4 min",IF(G7<=6,"6-8 min","10-12 min")) -> 3-4 min | I7: PY-05 | J7: =IF(COUNTIFS(Python!$C$2:$C$121,C7,Python!$I$2:$I$121,"Done")=G7,"Done",IF(COUNTIFS(Python!$C$2:$C$121,C7,Python!$I$2:$I$121,"Not Started")=G7,"Not Started","In Progress")) -> Not Started
A8: 7 | B8: 1. Python Core | C8: PY-07 | D8: Python | E8: Errors, Files & Config | F8: P1 | G8: =COUNTIF(Python!$C$2:$C$121,C8) -> 6 | H8: =IF(G8<=4,"3-4 min",IF(G8<=6,"6-8 min","10-12 min")) -> 6-8 min | I8: PY-06 | J8: =IF(COUNTIFS(Python!$C$2:$C$121,C8,Python!$I$2:$I$121,"Done")=G8,"Done",IF(COUNTIFS(Python!$C$2:$C$121,C8,Python!$I$2:$I$121,"Not Started")=G8,"Not Started","In Progress")) -> Not Started
A9: 8 | B9: 1. Python Core | C9: PY-08 | D9: Python | E9: Type Hints | F9: P1 | G9: =COUNTIF(Python!$C$2:$C$121,C9) -> 4 | H9: =IF(G9<=4,"3-4 min",IF(G9<=6,"6-8 min","10-12 min")) -> 3-4 min | I9: PY-07 | J9: =IF(COUNTIFS(Python!$C$2:$C$121,C9,Python!$I$2:$I$121,"Done")=G9,"Done",IF(COUNTIFS(Python!$C$2:$C$121,C9,Python!$I$2:$I$121,"Not Started")=G9,"Not Started","In Progress")) -> Not Started
A10: 9 | B10: 1. Python Core | C10: PY-09 | D10: Python | E10: Pydantic | F10: P1 | G10: =COUNTIF(Python!$C$2:$C$121,C10) -> 4 | H10: =IF(G10<=4,"3-4 min",IF(G10<=6,"6-8 min","10-12 min")) -> 3-4 min | I10: PY-08 | J10: =IF(COUNTIFS(Python!$C$2:$C$121,C10,Python!$I$2:$I$121,"Done")=G10,"Done",IF(COUNTIFS(Python!$C$2:$C$121,C10,Python!$I$2:$I$121,"Not Started")=G10,"Not Started","In Progress")) -> Not Started
A11: 10 | B11: 2. LLM Basics + API | C11: GA-01 | D11: GenAI | E11: How LLMs Work | F11: P1 | G11: =COUNTIF(GenAI!$C$2:$C$150,C11) -> 6 | H11: =IF(G11<=4,"3-4 min",IF(G11<=6,"6-8 min","10-12 min")) -> 6-8 min | I11: PY-09 | J11: =IF(COUNTIFS(GenAI!$C$2:$C$150,C11,GenAI!$I$2:$I$150,"Done")=G11,"Done",IF(COUNTIFS(GenAI!$C$2:$C$150,C11,GenAI!$I$2:$I$150,"Not Started")=G11,"Not Started","In Progress")) -> Not Started
A12: 11 | B12: 2. LLM Basics + API | C12: GA-02 | D12: GenAI | E12: Model Landscape | F12: P1 | G12: =COUNTIF(GenAI!$C$2:$C$150,C12) -> 5 | H12: =IF(G12<=4,"3-4 min",IF(G12<=6,"6-8 min","10-12 min")) -> 6-8 min | I12: GA-01 | J12: =IF(COUNTIFS(GenAI!$C$2:$C$150,C12,GenAI!$I$2:$I$150,"Done")=G12,"Done",IF(COUNTIFS(GenAI!$C$2:$C$150,C12,GenAI!$I$2:$I$150,"Not Started")=G12,"Not Started","In Progress")) -> Not Started
A13: 12 | B13: 2. LLM Basics + API | C13: GA-03 | D13: GenAI | E13: API Basics | F13: P1 | G13: =COUNTIF(GenAI!$C$2:$C$150,C13) -> 6 | H13: =IF(G13<=4,"3-4 min",IF(G13<=6,"6-8 min","10-12 min")) -> 6-8 min | I13: GA-02 | J13: =IF(COUNTIFS(GenAI!$C$2:$C$150,C13,GenAI!$I$2:$I$150,"Done")=G13,"Done",IF(COUNTIFS(GenAI!$C$2:$C$150,C13,GenAI!$I$2:$I$150,"Not Started")=G13,"Not Started","In Progress")) -> Not Started
A14: 13 | B14: 2. LLM Basics + API | C14: GA-04 | D14: GenAI | E14: Structured Output & Tools | F14: P1 | G14: =COUNTIF(GenAI!$C$2:$C$150,C14) -> 5 | H14: =IF(G14<=4,"3-4 min",IF(G14<=6,"6-8 min","10-12 min")) -> 6-8 min | I14: GA-03 | J14: =IF(COUNTIFS(GenAI!$C$2:$C$150,C14,GenAI!$I$2:$I$150,"Done")=G14,"Done",IF(COUNTIFS(GenAI!$C$2:$C$150,C14,GenAI!$I$2:$I$150,"Not Started")=G14,"Not Started","In Progress")) -> Not Started
A15: 14 | B15: 2. LLM Basics + API | C15: GA-05 | D15: GenAI | E15: Core Techniques | F15: P1 | G15: =COUNTIF(GenAI!$C$2:$C$150,C15) -> 6 | H15: =IF(G15<=4,"3-4 min",IF(G15<=6,"6-8 min","10-12 min")) -> 6-8 min | I15: GA-04 | J15: =IF(COUNTIFS(GenAI!$C$2:$C$150,C15,GenAI!$I$2:$I$150,"Done")=G15,"Done",IF(COUNTIFS(GenAI!$C$2:$C$150,C15,GenAI!$I$2:$I$150,"Not Started")=G15,"Not Started","In Progress")) -> Not Started
A16: 15 | B16: 2. LLM Basics + API | C16: GA-06 | D16: GenAI | E16: Prompt Lifecycle | F16: P2 | G16: =COUNTIF(GenAI!$C$2:$C$150,C16) -> 4 | H16: =IF(G16<=4,"3-4 min",IF(G16<=6,"6-8 min","10-12 min")) -> 3-4 min | I16: GA-05 | J16: =IF(COUNTIFS(GenAI!$C$2:$C$150,C16,GenAI!$I$2:$I$150,"Done")=G16,"Done",IF(COUNTIFS(GenAI!$C$2:$C$150,C16,GenAI!$I$2:$I$150,"Not Started")=G16,"Not Started","In Progress")) -> Not Started
A17: 16 | B17: 3. Python for Data | C17: PY-24 | D17: Python | E17: NumPy & Vectors | F17: P1 | G17: =COUNTIF(Python!$C$2:$C$121,C17) -> 4 | H17: =IF(G17<=4,"3-4 min",IF(G17<=6,"6-8 min","10-12 min")) -> 3-4 min | I17: PY-09 | J17: =IF(COUNTIFS(Python!$C$2:$C$121,C17,Python!$I$2:$I$121,"Done")=G17,"Done",IF(COUNTIFS(Python!$C$2:$C$121,C17,Python!$I$2:$I$121,"Not Started")=G17,"Not Started","In Progress")) -> Not Started
A18: 17 | B18: 3. Python for Data | C18: PY-25 | D18: Python | E18: ML Basics | F18: P2 | G18: =COUNTIF(Python!$C$2:$C$121,C18) -> 5 | H18: =IF(G18<=4,"3-4 min",IF(G18<=6,"6-8 min","10-12 min")) -> 6-8 min | I18: PY-24 | J18: =IF(COUNTIFS(Python!$C$2:$C$121,C18,Python!$I$2:$I$121,"Done")=G18,"Done",IF(COUNTIFS(Python!$C$2:$C$121,C18,Python!$I$2:$I$121,"Not Started")=G18,"Not Started","In Progress")) -> Not Started
A19: 18 | B19: 3. Python for Data | C19: PY-15 | D19: Python | E19: pandas | F19: P1 | G19: =COUNTIF(Python!$C$2:$C$121,C19) -> 6 | H19: =IF(G19<=4,"3-4 min",IF(G19<=6,"6-8 min","10-12 min")) -> 6-8 min | I19: PY-24 | J19: =IF(COUNTIFS(Python!$C$2:$C$121,C19,Python!$I$2:$I$121,"Done")=G19,"Done",IF(COUNTIFS(Python!$C$2:$C$121,C19,Python!$I$2:$I$121,"Not Started")=G19,"Not Started","In Progress")) -> Not Started
A20: 19 | B20: 3. Python for Data | C20: PY-17 | D20: Python | E20: File Formats | F20: P1 | G20: =COUNTIF(Python!$C$2:$C$121,C20) -> 6 | H20: =IF(G20<=4,"3-4 min",IF(G20<=6,"6-8 min","10-12 min")) -> 6-8 min | I20: PY-15 | J20: =IF(COUNTIFS(Python!$C$2:$C$121,C20,Python!$I$2:$I$121,"Done")=G20,"Done",IF(COUNTIFS(Python!$C$2:$C$121,C20,Python!$I$2:$I$121,"Not Started")=G20,"Not Started","In Progress")) -> Not Started
A21: 20 | B21: 3. Python for Data | C21: PY-18 | D21: Python | E21: DuckDB | F21: P1 | G21: =COUNTIF(Python!$C$2:$C$121,C21) -> 6 | H21: =IF(G21<=4,"3-4 min",IF(G21<=6,"6-8 min","10-12 min")) -> 6-8 min | I21: PY-17 | J21: =IF(COUNTIFS(Python!$C$2:$C$121,C21,Python!$I$2:$I$121,"Done")=G21,"Done",IF(COUNTIFS(Python!$C$2:$C$121,C21,Python!$I$2:$I$121,"Not Started")=G21,"Not Started","In Progress")) -> Not Started
A22: 21 | B22: 3. Python for Data | C22: PY-19 | D22: Python | E22: Excel Automation | F22: P1 | G22: =COUNTIF(Python!$C$2:$C$121,C22) -> 6 | H22: =IF(G22<=4,"3-4 min",IF(G22<=6,"6-8 min","10-12 min")) -> 6-8 min | I22: PY-18 | J22: =IF(COUNTIFS(Python!$C$2:$C$121,C22,Python!$I$2:$I$121,"Done")=G22,"Done",IF(COUNTIFS(Python!$C$2:$C$121,C22,Python!$I$2:$I$121,"Not Started")=G22,"Not Started","In Progress")) -> Not Started
A23: 22 | B23: 4. Embeddings > Vector DB > RAG | C23: GA-07 | D23: GenAI | E23: Embedding Concepts | F23: P1 | G23: =COUNTIF(GenAI!$C$2:$C$150,C23) -> 5 | H23: =IF(G23<=4,"3-4 min",IF(G23<=6,"6-8 min","10-12 min")) -> 6-8 min | I23: PY-24, GA-01 | J23: =IF(COUNTIFS(GenAI!$C$2:$C$150,C23,GenAI!$I$2:$I$150,"Done")=G23,"Done",IF(COUNTIFS(GenAI!$C$2:$C$150,C23,GenAI!$I$2:$I$150,"Not Started")=G23,"Not Started","In Progress")) -> Not Started
A24: 23 | B24: 4. Embeddings > Vector DB > RAG | C24: GA-08 | D24: GenAI | E24: Embedding Models | F24: P1 | G24: =COUNTIF(GenAI!$C$2:$C$150,C24) -> 4 | H24: =IF(G24<=4,"3-4 min",IF(G24<=6,"6-8 min","10-12 min")) -> 3-4 min | I24: GA-07 | J24: =IF(COUNTIFS(GenAI!$C$2:$C$150,C24,GenAI!$I$2:$I$150,"Done")=G24,"Done",IF(COUNTIFS(GenAI!$C$2:$C$150,C24,GenAI!$I$2:$I$150,"Not Started")=G24,"Not Started","In Progress")) -> Not Started
A25: 24 | B25: 4. Embeddings > Vector DB > RAG | C25: PY-20 | D25: Python | E25: SQL from Python | F25: P1 | G25: =COUNTIF(Python!$C$2:$C$121,C25) -> 6 | H25: =IF(G25<=4,"3-4 min",IF(G25<=6,"6-8 min","10-12 min")) -> 6-8 min | I25: PY-15 | J25: =IF(COUNTIFS(Python!$C$2:$C$121,C25,Python!$I$2:$I$121,"Done")=G25,"Done",IF(COUNTIFS(Python!$C$2:$C$121,C25,Python!$I$2:$I$121,"Not Started")=G25,"Not Started","In Progress")) -> Not Started
A26: 25 | B26: 4. Embeddings > Vector DB > RAG | C26: GA-09 | D26: GenAI | E26: Vector DB Fundamentals | F26: P1 | G26: =COUNTIF(GenAI!$C$2:$C$150,C26) -> 6 | H26: =IF(G26<=4,"3-4 min",IF(G26<=6,"6-8 min","10-12 min")) -> 6-8 min | I26: GA-08, PY-20 | J26: =IF(COUNTIFS(GenAI!$C$2:$C$150,C26,GenAI!$I$2:$I$150,"Done")=G26,"Done",IF(COUNTIFS(GenAI!$C$2:$C$150,C26,GenAI!$I$2:$I$150,"Not Started")=G26,"Not Started","In Progress")) -> Not Started
A27: 26 | B27: 4. Embeddings > Vector DB > RAG | C27: GA-10 | D27: GenAI | E27: Vector DB Options | F27: P1 | G27: =COUNTIF(GenAI!$C$2:$C$150,C27) -> 6 | H27: =IF(G27<=4,"3-4 min",IF(G27<=6,"6-8 min","10-12 min")) -> 6-8 min | I27: GA-09 | J27: =IF(COUNTIFS(GenAI!$C$2:$C$150,C27,GenAI!$I$2:$I$150,"Done")=G27,"Done",IF(COUNTIFS(GenAI!$C$2:$C$150,C27,GenAI!$I$2:$I$150,"Not Started")=G27,"Not Started","In Progress")) -> Not Started
A28: 27 | B28: 4. Embeddings > Vector DB > RAG | C28: GA-11 | D28: GenAI | E28: Operations | F28: P2 | G28: =COUNTIF(GenAI!$C$2:$C$150,C28) -> 4 | H28: =IF(G28<=4,"3-4 min",IF(G28<=6,"6-8 min","10-12 min")) -> 3-4 min | I28: GA-10 | J28: =IF(COUNTIFS(GenAI!$C$2:$C$150,C28,GenAI!$I$2:$I$150,"Done")=G28,"Done",IF(COUNTIFS(GenAI!$C$2:$C$150,C28,GenAI!$I$2:$I$150,"Not Started")=G28,"Not Started","In Progress")) -> Not Started
A29: 28 | B29: 4. Embeddings > Vector DB > RAG | C29: GA-12 | D29: GenAI | E29: Vector vs Parquet/SQL Decision | F29: P1 | G29: =COUNTIF(GenAI!$C$2:$C$150,C29) -> 4 | H29: =IF(G29<=4,"3-4 min",IF(G29<=6,"6-8 min","10-12 min")) -> 3-4 min | I29: GA-11 | J29: =IF(COUNTIFS(GenAI!$C$2:$C$150,C29,GenAI!$I$2:$I$150,"Done")=G29,"Done",IF(COUNTIFS(GenAI!$C$2:$C$150,C29,GenAI!$I$2:$I$150,"Not Started")=G29,"Not Started","In Progress")) -> Not Started
A30: 29 | B30: 4. Embeddings > Vector DB > RAG | C30: GA-13 | D30: GenAI | E30: RAG Architecture | F30: P1 | G30: =COUNTIF(GenAI!$C$2:$C$150,C30) -> 4 | H30: =IF(G30<=4,"3-4 min",IF(G30<=6,"6-8 min","10-12 min")) -> 3-4 min | I30: GA-09, GA-12 | J30: =IF(COUNTIFS(GenAI!$C$2:$C$150,C30,GenAI!$I$2:$I$150,"Done")=G30,"Done",IF(COUNTIFS(GenAI!$C$2:$C$150,C30,GenAI!$I$2:$I$150,"Not Started")=G30,"Not Started","In Progress")) -> Not Started
A31: 30 | B31: 4. Embeddings > Vector DB > RAG | C31: GA-14 | D31: GenAI | E31: Ingestion & Chunking | F31: P1 | G31: =COUNTIF(GenAI!$C$2:$C$150,C31) -> 6 | H31: =IF(G31<=4,"3-4 min",IF(G31<=6,"6-8 min","10-12 min")) -> 6-8 min | I31: GA-13 | J31: =IF(COUNTIFS(GenAI!$C$2:$C$150,C31,GenAI!$I$2:$I$150,"Done")=G31,"Done",IF(COUNTIFS(GenAI!$C$2:$C$150,C31,GenAI!$I$2:$I$150,"Not Started")=G31,"Not Started","In Progress")) -> Not Started
A32: 31 | B32: 4. Embeddings > Vector DB > RAG | C32: GA-15 | D32: GenAI | E32: Retrieval Quality | F32: P1 | G32: =COUNTIF(GenAI!$C$2:$C$150,C32) -> 5 | H32: =IF(G32<=4,"3-4 min",IF(G32<=6,"6-8 min","10-12 min")) -> 6-8 min | I32: GA-14 | J32: =IF(COUNTIFS(GenAI!$C$2:$C$150,C32,GenAI!$I$2:$I$150,"Done")=G32,"Done",IF(COUNTIFS(GenAI!$C$2:$C$150,C32,GenAI!$I$2:$I$150,"Not Started")=G32,"Not Started","In Progress")) -> Not Started
A33: 32 | B33: 4. Embeddings > Vector DB > RAG | C33: GA-16 | D33: GenAI | E33: Generation & Citations | F33: P1 | G33: =COUNTIF(GenAI!$C$2:$C$150,C33) -> 4 | H33: =IF(G33<=4,"3-4 min",IF(G33<=6,"6-8 min","10-12 min")) -> 3-4 min | I33: GA-15 | J33: =IF(COUNTIFS(GenAI!$C$2:$C$150,C33,GenAI!$I$2:$I$150,"Done")=G33,"Done",IF(COUNTIFS(GenAI!$C$2:$C$150,C33,GenAI!$I$2:$I$150,"Not Started")=G33,"Not Started","In Progress")) -> Not Started
A34: 33 | B34: 4. Embeddings > Vector DB > RAG | C34: GA-17 | D34: GenAI | E34: Advanced RAG | F34: P2 | G34: =COUNTIF(GenAI!$C$2:$C$150,C34) -> 5 | H34: =IF(G34<=4,"3-4 min",IF(G34<=6,"6-8 min","10-12 min")) -> 6-8 min | I34: GA-16 | J34: =IF(COUNTIFS(GenAI!$C$2:$C$150,C34,GenAI!$I$2:$I$150,"Done")=G34,"Done",IF(COUNTIFS(GenAI!$C$2:$C$150,C34,GenAI!$I$2:$I$150,"Not Started")=G34,"Not Started","In Progress")) -> Not Started
A35: 34 | B35: 5. App Building + Quality | C35: PY-10 | D35: Python | E35: asyncio | F35: P1 | G35: =COUNTIF(Python!$C$2:$C$121,C35) -> 6 | H35: =IF(G35<=4,"3-4 min",IF(G35<=6,"6-8 min","10-12 min")) -> 6-8 min | I35: PY-09 | J35: =IF(COUNTIFS(Python!$C$2:$C$121,C35,Python!$I$2:$I$121,"Done")=G35,"Done",IF(COUNTIFS(Python!$C$2:$C$121,C35,Python!$I$2:$I$121,"Not Started")=G35,"Not Started","In Progress")) -> Not Started
A36: 35 | B36: 5. App Building + Quality | C36: PY-11 | D36: Python | E36: Threads vs Processes | F36: P2 | G36: =COUNTIF(Python!$C$2:$C$121,C36) -> 4 | H36: =IF(G36<=4,"3-4 min",IF(G36<=6,"6-8 min","10-12 min")) -> 3-4 min | I36: PY-10 | J36: =IF(COUNTIFS(Python!$C$2:$C$121,C36,Python!$I$2:$I$121,"Done")=G36,"Done",IF(COUNTIFS(Python!$C$2:$C$121,C36,Python!$I$2:$I$121,"Not Started")=G36,"Not Started","In Progress")) -> Not Started
A37: 36 | B37: 5. App Building + Quality | C37: PY-12 | D37: Python | E37: HTTP Clients | F37: P1 | G37: =COUNTIF(Python!$C$2:$C$121,C37) -> 4 | H37: =IF(G37<=4,"3-4 min",IF(G37<=6,"6-8 min","10-12 min")) -> 3-4 min | I37: PY-11 | J37: =IF(COUNTIFS(Python!$C$2:$C$121,C37,Python!$I$2:$I$121,"Done")=G37,"Done",IF(COUNTIFS(Python!$C$2:$C$121,C37,Python!$I$2:$I$121,"Not Started")=G37,"Not Started","In Progress")) -> Not Started
A38: 37 | B38: 5. App Building + Quality | C38: PY-13 | D38: Python | E38: FastAPI | F38: P1 | G38: =COUNTIF(Python!$C$2:$C$121,C38) -> 8 | H38: =IF(G38<=4,"3-4 min",IF(G38<=6,"6-8 min","10-12 min")) -> 10-12 min | I38: PY-12 | J38: =IF(COUNTIFS(Python!$C$2:$C$121,C38,Python!$I$2:$I$121,"Done")=G38,"Done",IF(COUNTIFS(Python!$C$2:$C$121,C38,Python!$I$2:$I$121,"Not Started")=G38,"Not Started","In Progress")) -> Not Started
A39: 38 | B39: 5. App Building + Quality | C39: PY-22 | D39: Python | E39: Testing & Quality | F39: P1 | G39: =COUNTIF(Python!$C$2:$C$121,C39) -> 5 | H39: =IF(G39<=4,"3-4 min",IF(G39<=6,"6-8 min","10-12 min")) -> 6-8 min | I39: PY-13 | J39: =IF(COUNTIFS(Python!$C$2:$C$121,C39,Python!$I$2:$I$121,"Done")=G39,"Done",IF(COUNTIFS(Python!$C$2:$C$121,C39,Python!$I$2:$I$121,"Not Started")=G39,"Not Started","In Progress")) -> Not Started
A40: 39 | B40: 5. App Building + Quality | C40: GA-20 | D40: GenAI | E40: Eval Fundamentals | F40: P1 | G40: =COUNTIF(GenAI!$C$2:$C$150,C40) -> 4 | H40: =IF(G40<=4,"3-4 min",IF(G40<=6,"6-8 min","10-12 min")) -> 3-4 min | I40: GA-13 | J40: =IF(COUNTIFS(GenAI!$C$2:$C$150,C40,GenAI!$I$2:$I$150,"Done")=G40,"Done",IF(COUNTIFS(GenAI!$C$2:$C$150,C40,GenAI!$I$2:$I$150,"Not Started")=G40,"Not Started","In Progress")) -> Not Started
...

Sheet Python
A1: Seq # | B1: Stage | C1: Reel ID | D1: Module | E1: Topic (1 Reel) | F1: Subtopic | G1: What it is (one line) | H1: Priority | I1: Learning Status | J1: Reel Script Status
A2: 1 | B2: 1. Python Core | C2: PY-01 | D2: 1. Python Foundations (C# mapping) | E2: Setup & Tooling | F2: Python versions & install | G2: Pick one stable version, manage multiple | H2: P1 | I2: Not Started | J2: Not Started
A3: 1 | B3: 1. Python Core | C3: PY-01 | D3: 1. Python Foundations (C# mapping) | E3: Setup & Tooling | F3: venv & uv/pip | G3: Isolated environments (like per-project NuGet) | H3: P1 | I3: Not Started | J3: Not Started
A4: 1 | B4: 1. Python Core | C4: PY-01 | D4: 1. Python Foundations (C# mapping) | E4: Setup & Tooling | F4: pyproject.toml & requirements | G4: Dependency declaration, lockfiles | H4: P1 | I4: Not Started | J4: Not Started
A5: 1 | B5: 1. Python Core | C5: PY-01 | D5: 1. Python Foundations (C# mapping) | E5: Setup & Tooling | F5: IDE setup | G5: VS Code / PyCharm, debugger, formatter | H5: P1 | I5: Not Started | J5: Not Started
A6: 1 | B6: 1. Python Core | C6: PY-01 | D6: 1. Python Foundations (C# mapping) | E6: Setup & Tooling | F6: Jupyter notebooks | G6: Quick experiments for data & LLM work | H6: P1 | I6: Not Started | J6: Not Started
A7: 2 | B7: 1. Python Core | C7: PY-02 | D7: 1. Python Foundations (C# mapping) | E7: Syntax Basics | F7: Dynamic typing | G7: No compile-time types, what that means | H7: P1 | I7: Not Started | J7: Not Started
A8: 2 | B8: 1. Python Core | C8: PY-02 | D8: 1. Python Foundations (C# mapping) | E8: Syntax Basics | F8: Indentation & blocks | G8: Whitespace is syntax | H8: P1 | I8: Not Started | J8: Not Started
A9: 2 | B9: 1. Python Core | C9: PY-02 | D9: 1. Python Foundations (C# mapping) | E9: Syntax Basics | F9: f-strings & formatting | G9: String interpolation | H9: P1 | I9: Not Started | J9: Not Started
A10: 2 | B10: 1. Python Core | C10: PY-02 | D10: 1. Python Foundations (C# mapping) | E10: Syntax Basics | F10: None, truthiness | G10: null vs None, falsy values | H10: P1 | I10: Not Started | J10: Not Started
A11: 2 | B11: 1. Python Core | C11: PY-02 | D11: 1. Python Foundations (C# mapping) | E11: Syntax Basics | F11: Operators & ranges | G11: is vs ==, in, range() | H11: P1 | I11: Not Started | J11: Not Started
A12: 3 | B12: 1. Python Core | C12: PY-03 | D12: 1. Python Foundations (C# mapping) | E12: Core Data Structures | F12: list & tuple | G12: Mutable vs immutable sequences | H12: P1 | I12: Not Started | J12: Not Started
A13: 3 | B13: 1. Python Core | C13: PY-03 | D13: 1. Python Foundations (C# mapping) | E13: Core Data Structures | F13: dict | G13: Hash map, the most-used structure | H13: P1 | I13: Not Started | J13: Not Started
... A121: 80 | B121: 10. Architect Layer + Extras | C121: PY-21 | D121: 6. Databases | E121: NoSQL & Cache | F121: Cosmos DB / MongoDB overview | G121: Document stores | H121: P3 | I121: Not Started | J121: Not Started

Sheet GenAI
A1: Seq # | B1: Stage | C1: Reel ID | D1: Module | E1: Topic (1 Reel) | F1: Subtopic | G1: What it is (one line) | H1: Priority | I1: Learning Status | J1: Reel Script Status
A2: 10 | B2: 2. LLM Basics + API | C2: GA-01 | D2: 1. LLM Foundations | E2: How LLMs Work | F2: What is GenAI | G2: Generative vs predictive AI | H2: P1 | I2: Not Started | J2: Not Started
A3: 10 | B3: 2. LLM Basics + API | C3: GA-01 | D3: 1. LLM Foundations | E3: How LLMs Work | F3: Transformer & attention intuition | G3: No heavy math, just the idea | H3: P1 | I3: Not Started | J3: Not Started
A4: 10 | B4: 2. LLM Basics + API | C4: GA-01 | D4: 1. LLM Foundations | E4: How LLMs Work | F4: Tokens & tokenization | G4: Cost and limits are token-based | H4: P1 | I4: Not Started | J4: Not Started
A5: 10 | B5: 2. LLM Basics + API | C5: GA-01 | D5: 1. LLM Foundations | E5: How LLMs Work | F5: Context window | G5: Memory limit per call | H5: P1 | I5: Not Started | J5: Not Started
A6: 10 | B6: 2. LLM Basics + API | C6: GA-01 | D6: 1. LLM Foundations | E6: How LLMs Work | F6: Sampling params | G6: Temperature, top-p, max tokens | H6: P1 | I6: Not Started | J6: Not Started
A7: 10 | B7: 2. LLM Basics + API | C7: GA-01 | D7: 1. LLM Foundations | E7: How LLMs Work | F7: Training stages | G7: Pretrain, fine-tune, RLHF | H7: P1 | I7: Not Started | J7: Not Started
A8: 11 | B8: 2. LLM Basics + API | C8: GA-02 | D8: 1. LLM Foundations | E8: Model Landscape | F8: Model families | G8: Frontier, small, open-weight | H8: P1 | I8: Not Started | J8: Not Started
A9: 11 | B9: 2. LLM Basics + API | C9: GA-02 | D9: 1. LLM Foundations | E9: Model Landscape | F9: Reasoning vs standard models | G9: When thinking models help | H9: P1 | I9: Not Started | J9: Not Started
A10: 11 | B10: 2. LLM Basics + API | C10: GA-02 | D10: 1. LLM Foundations | E10: Model Landscape | F10: Multimodal models | G10: Text, image, audio | H10: P1 | I10: Not Started | J10: Not Started
A11: 11 | B11: 2. LLM Basics + API | C11: GA-02 | D11: 1. LLM Foundations | E11: Model Landscape | F11: Selection criteria | G11: Quality, cost, latency, privacy | H11: P1 | I11: Not Started | J11: Not Started
A12: 11 | B12: 2. LLM Basics + API | C12: GA-02 | D12: 1. LLM Foundations | E12: Model Landscape | F12: Hallucination & limits | G12: Why LLMs are confidently wrong | H12: P1 | I12: Not Started | J12: Not Started
A13: 12 | B13: 2. LLM Basics + API | C13: GA-03 | D13: 2. LLM API Usage | E13: API Basics | F13: Chat API anatomy | G13: System / user / assistant messages | H13: P1 | I13: Not Started | J13: Not Started
... A150: 77 | B150: 10. Architect Layer + Extras | C150: GA-28 | D150: 12. Multimodal & Voice | E150: Beyond Text | F150: Image generation basics | G150: Use cases and limits | H150: P3 | I150: Not Started | J150: Not Started

Sheet Agentic AI
A1: Seq # | B1: Stage | C1: Reel ID | D1: Module | E1: Topic (1 Reel) | F1: Subtopic | G1: What it is (one line) | H1: Priority | I1: Learning Status | J1: Reel Script Status
A2: 41 | B2: 6. Agents Core + MCP | C2: AG-01 | D2: 1. Agent Foundations | E2: What is an Agent | F2: Chatbot vs workflow vs agent | G2: Autonomy spectrum | H2: P1 | I2: Not Started | J2: Not Started
A3: 41 | B3: 6. Agents Core + MCP | C3: AG-01 | D3: 1. Agent Foundations | E3: What is an Agent | F3: Agent loop | G3: Think -> act -> observe -> repeat | H3: P1 | I3: Not Started | J3: Not Started
A4: 41 | B4: 6. Agents Core + MCP | C4: AG-01 | D4: 1. Agent Foundations | E4: What is an Agent | F4: Anatomy | G4: Model, instructions, tools, memory | H4: P1 | I4: Not Started | J4: Not Started
A5: 41 | B5: 6. Agents Core + MCP | C5: AG-01 | D5: 1. Agent Foundations | E5: What is an Agent | F5: When NOT to use agents | G5: Workflow is often better | H5: P1 | I5: Not Started | J5: Not Started
A6: 41 | B6: 6. Agents Core + MCP | C6: AG-01 | D6: 1. Agent Foundations | E6: What is an Agent | F6: Single vs multi-agent | G6: Start simple | H6: P1 | I6: Not Started | J6: Not Started
A7: 42 | B7: 6. Agents Core + MCP | C7: AG-02 | D7: 2. Tool Use | E7: Tool Design | F7: Tool schema & descriptions | G7: Descriptions drive tool selection | H7: P1 | I7: Not Started | J7: Not Started
A8: 42 | B8: 6. Agents Core + MCP | C8: AG-02 | D8: 2. Tool Use | E8: Tool Design | F8: Input validation | G8: Never trust LLM-generated args | H8: P1 | I8: Not Started | J8: Not Started
A9: 42 | B9: 6. Agents Core + MCP | C9: AG-02 | D9: 2. Tool Use | E9: Tool Design | F9: Error messages the LLM can fix | G9: Actionable failures | H9: P1 | I9: Not Started | J9: Not Started
A10: 42 | B10: 6. Agents Core + MCP | C10: AG-02 | D10: 2. Tool Use | E10: Tool Design | F10: Idempotency | G10: Safe retries | H10: P1 | I10: Not Started | J10: Not Started
A11: 42 | B11: 6. Agents Core + MCP | C11: AG-02 | D11: 2. Tool Use | E11: Tool Design | F11: Parallel tool calls | G11: Speed up independent actions | H11: P1 | I11: Not Started | J11: Not Started
A12: 42 | B12: 6. Agents Core + MCP | C12: AG-02 | D12: 2. Tool Use | E12: Tool Design | F12: Too many tools problem | G12: Tool selection and grouping | H12: P1 | I12: Not Started | J12: Not Started
A13: 43 | B13: 6. Agents Core + MCP | C13: AG-03 | D13: 2. Tool Use | E13: Built-in Capabilities | F13: Code execution sandbox | G13: Run generated code safely | H13: P2 | I13: Not Started | J13: Not Started
... A124: 75 | B124: 10. Architect Layer + Extras | C124: AG-25 | D124: 14. Agentic Solution Architecture | E124: Architect Toolkit | F124: Build vs buy vs configure | G124: Decision framework | H124: P1 | I124: Not Started | J124: Not Started
